Workbook

Sheet PM I
A1: NF 1 PM I | F1: NF 1 BiP | J1: NF 1 PM I vs BiP
A2: Hours | B2: Area | C2: Percent | D2: Rel density | F2: Area | G2: Percent | H2: Rel density | J2: A PM I/ A BiP | K2: Percent/percent | L2: Rel Dens/ Rel Dens
A3: 20 | B3: 11993.903 | C3: 11.242 | D3: =C3/$C$3 -> 1 | F3: 5426.861 | G3: 6.77 | H3: =G3/$G$3 -> 1 | J3: =B3/F3 -> 2.2100995 | K3: =C3/G3 -> 1.6605613 | L3: =D3/H3 -> 1
A4: =A3+4 -> 24 | B4: 6235.196 | C4: 5.844 | D4: =C4/$C$3 -> 0.51983633 | F4: 7752.711 | G4: 9.671 | H4: =G4/$G$3 -> 1.4285081 | J4: =B4/F4 -> 0.80426008 | K4: =C4/G4 -> 0.60428084 | L4: =D4/H4 -> 0.36390156
A5: =A4+4 -> 28 | B5: 13270.51 | C5: 12.439 | D5: =C5/$C$3 -> 1.1064757 | F5: 7439.761 | G5: 9.281 | H5: =G5/$G$3 -> 1.370901 | J5: =B5/F5 -> 1.783728 | K5: =C5/G5 -> 1.3402651 | L5: =D5/H5 -> 0.80711568
A6: =A5+4 -> 32 | B6: 16037.924 | C6: 15.033 | D6: =C6/$C$3 -> 1.3372176 | F6: 10852.075 | G6: 13.537 | H6: =G6/$G$3 -> 1.9995569 | J6: =B6/F6 -> 1.477867 | K6: =C6/G6 -> 1.1105119 | L6: =D6/H6 -> 0.66875696
A7: =A6+4 -> 36 | B7: 17190.045 | C7: 16.113 | D7: =C7/$C$3 -> 1.4332859 | F7: 14625.974 | G7: 18.245 | H7: =G7/$G$3 -> 2.6949778 | J7: =B7/F7 -> 1.1753094 | K7: =C7/G7 -> 0.88314607 | L7: =D7/H7 -> 0.53183587
A8: =A7+4 -> 40 | B8: 20493.752 | C8: 19.209 | D8: =C8/$C$3 -> 1.7086817 | F8: 16746.338 | G8: 20.89 | H8: =G8/$G$3 -> 3.0856721 | J8: =B8/F8 -> 1.2237751 | K8: =C8/G8 -> 0.91953088 | L8: =D8/H8 -> 0.55374702
A9: =A8+4 -> 44 | B9: 21465.581 | C9: 20.12 | D9: =C9/$C$3 -> 1.7897171 | F9: 17321.217 | G9: 21.607 | H9: =G9/$G$3 -> 3.1915805 | J9: =B9/F9 -> 1.2392652 | K9: =C9/G9 -> 0.93117971 | L9: =D9/H9 -> 0.56076202
A11: NF 2 PM I | F11: NF 2 BiP | J11: NF 2 PM I vs BiP
A12: Hours | B12: Area | C12: Percent | D12: Rel Density | F12: Area | G12: Percent | H12: Rel Density | J12: A/A | K12: P/P | L12: Rel dens / Rel dens
A13: 20 | B13: 5715.711 | C13: 9.544 | D13: =C13/$C$13 -> 1 | F13: 607.284 | G13: 1.09 | H13: =G13/$G$13 -> 1 | J13: =B13/F13 -> 9.4119242 | K13: =C13/G13 -> 8.7559633 | L13: =D13/H13 -> 1
A14: =A13+4 -> 24 | B14: 2045.033 | C14: 3.415 | D14: =C14/$C$13 -> 0.35781643 | F14: 3162.962 | G14: 5.676 | H14: =G14/$G$13 -> 5.2073394 | J14: =B14/F14 -> 0.6465563 | K14: =C14/G14 -> 0.6016561 | L14: =D14/H14 -> 0.068713867
A15: =A14+4 -> 28 | B15: 5355.64 | C15: 8.943 | D15: =C15/$C$13 -> 0.9370285 | F15: 1353.77 | G15: 2.429 | H15: =G15/$G$13 -> 2.2284404 | J15: =B15/F15 -> 3.956093 | K15: =C15/G15 -> 3.681762 | L15: =D15/H15 -> 0.42048623
A16: =A15+4 -> 32 | B16: 10915.317 | C16: 18.227 | D16: =C16/$C$13 -> 1.9097863 | F16: 7926.933 | G16: 14.225 | H16: =G16/$G$13 -> 13.050459 | J16: =B16/F16 -> 1.3769912 | K16: =C16/G16 -> 1.2813357 | L16: =D16/H16 -> 0.14633863
A17: =A16+4 -> 36 | B17: 10951.782 | C17: 18.288 | D17: =C17/$C$13 -> 1.9161777 | F17: 13735.903 | G17: 24.65 | H17: =G17/$G$13 -> 22.614679 | J17: =B17/F17 -> 0.79731067 | K17: =C17/G17 -> 0.74190669 | L17: =D17/H17 -> 0.08473159
A18: =A17+4 -> 40 | B18: 11700.004 | C18: 19.537 | D18: =C18/$C$13 -> 2.0470453 | F18: 14978.731 | G18: 26.88 | H18: =G18/$G$13 -> 24.66055 | J18: =B18/F18 -> 0.78110783 | K18: =C18/G18 -> 0.72682292 | L18: =D18/H18 -> 0.083008904
A19: =A18+4 -> 44 | B19: 13202.539 | C19: 22.046 | D19: =C19/$C$13 -> 2.3099329 | F19: 13958.782 | G19: 25.05 | H19: =G19/$G$13 -> 22.981651 | J19: =B19/F19 -> 0.94582314 | K19: =C19/G19 -> 0.88007984 | L19: =D19/H19 -> 0.10051205
A21: NF 3 PM I | F21: NF 3 BiP | J21: NF 3 PM I vs BiP
A22: Hours | B22: Area | C22: Percent | D22: Rel Density | F22: Area | G22: Percent | H22: Rel Density | J22: A/A | K22: P/P | L22: Rel dens / Rel dens
A23: 20 | B23: 10750.853 | C23: 10.576 | D23: =C23/$C$23 -> 1 | F23: 10126.125 | G23: 9.613 | H23: =G23/$G$23 -> 1 | J23: =B23/F23 -> 1.0616947 | K23: =C23/G23 -> 1.1001768 | L23: =D23/H23 -> 1
A24: =A23+4 -> 24 | B24: 10171.317 | C24: 10.006 | D24: =C24/$C$23 -> 0.94610439 | F24: 7119.518 | G24: 6.759 | H24: =G24/$G$23 -> 0.70311037 | J24: =B24/F24 -> 1.4286525 | K24: =C24/G24 -> 1.4803965 | L24: =D24/H24 -> 1.3455987
A25: =A24+4 -> 28 | B25: 11966.974 | C25: 11.772 | D25: =C25/$C$23 -> 1.1130862 | F25: 7563.468 | G25: 7.18 | H25: =G25/$G$23 -> 0.74690523 | J25: =B25/F25 -> 1.5822073 | K25: =C25/G25 -> 1.6395543 | L25: =D25/H25 -> 1.4902643
A26: =A25+4 -> 32 | B26: 16615.217 | C26: 16.345 | D26: =C26/$C$23 -> 1.5454803 | F26: 13063.489 | G26: 12.402 | H26: =G26/$G$23 -> 1.290128 | J26: =B26/F26 -> 1.271882 | K26: =C26/G26 -> 1.3179326 | L26: =D26/H26 -> 1.197928
A27: =A26+4 -> 36 | B27: 19760.56 | C27: 19.439 | D27: =C27/$C$23 -> 1.8380295 | F27: 20849.409 | G27: 19.793 | H27: =G27/$G$23 -> 2.0589826 | J27: =B27/F27 -> 0.94777555 | K27: =C27/G27 -> 0.98211489 | L27: =D27/H27 -> 0.8926882
A28: =A27+4 -> 40 | B28: 17871.924 | C28: 17.581 | D28: =C28/$C$23 -> 1.6623487 | F28: 22298.945 | G28: 21.17 | H28: =G28/$G$23 -> 2.2022262 | J28: =B28/F28 -> 0.80146949 | K28: =C28/G28 -> 0.83046764 | L28: =D28/H28 -> 0.75484923
A29: =A28+4 -> 44 | B29: 14517.338 | C29: 14.281 | D29: =C29/$C$23 -> 1.3503215 | F29: 24313.773 | G29: 23.082 | H29: =G29/$G$23 -> 2.4011235 | J29: =B29/F29 -> 0.5970829 | K29: =C29/G29 -> 0.61870722 | L29: =D29/H29 -> 0.5623707
A31: NF 4 PM I | F31: NF 4 BiP | J31: NF 4 PM I vs BiP
A32: Hours | B32: Area | C32: Percent | D32: Rel Density | F32: Area | G32: Percent | H32: Rel Density | J32: A/A | K32: P/P | L32: Rel dens / Rel dens
A33: 20 | B33: 6016.125 | C33: 7.596 | D33: =C33/$C$33 -> 1 | F33: 3143.497 | G33: 6.362 | H33: =G33/$G$33 -> 1 | J33: =B33/F33 -> 1.913832 | K33: =C33/G33 -> 1.1939642 | L33: =D33/H33 -> 1
A34: =A33+4 -> 24 | B34: 5972.004 | C34: 7.54 | D34: =C34/$C$33 -> 0.9926277 | F34: 2236.134 | G34: 4.525 | H34: =G34/$G$33 -> 0.71125432 | J34: =B34/F34 -> 2.6706825 | K34: =C34/G34 -> 1.6662983 | L34: =D34/H34 -> 1.3956016
A35: =A34+4 -> 28 | B35: 9085.368 | C35: 11.471 | D35: =C35/$C$33 -> 1.5101369 | F35: 1817.719 | G35: 3.679 | H35: =G35/$G$33 -> 0.57827727 | J35: =B35/F35 -> 4.9982247 | K35: =C35/G35 -> 3.1179668 | L35: =D35/H35 -> 2.6114409
A36: =A35+4 -> 32 | B36: 12054.439 | C36: 15.219 | D36: =C36/$C$33 -> 2.0035545 | F36: 5670.518 | G36: 11.475 | H36: =G36/$G$33 -> 1.8036781 | J36: =B36/F36 -> 2.1258091 | K36: =C36/G36 -> 1.3262745 | L36: =D36/H36 -> 1.110816
A37: =A36+4 -> 36 | B37: 11921.024 | C37: 15.051 | D37: =C37/$C$33 -> 1.9814376 | F37: 7241.296 | G37: 14.654 | H37: =G37/$G$33 -> 2.3033637 | J37: =B37/F37 -> 1.6462556 | K37: =C37/G37 -> 1.0270916 | L37: =D37/H37 -> 0.86023652
A38: =A37+4 -> 40 | B38: 17567.56 | C38: 22.18 | D38: =C38/$C$33 -> 2.9199579 | F38: 13772.217 | G38: 27.871 | H38: =G38/$G$33 -> 4.3808551 | J38: =B38/F38 -> 1.2755797 | K38: =C38/G38 -> 0.79580926 | L38: =D38/H38 -> 0.66652693
A39: =A38+4 -> 44 | B39: 16589.439 | C39: 20.945 | D39: =C39/$C$33 -> 2.7573723 | F39: 15532.974 | G39: 31.434 | H39: =G39/$G$33 -> 4.9408991 | J39: =B39/F39 -> 1.0680143 | K39: =C39/G39 -> 0.66631673 | L39: =D39/H39 -> 0.55807096
A41: Average of Percent values -PMI | J41: P/P Average
A42: Hours | B42: NF 1 | C42: NF 2 | D42: NF 3 | E42: NF 4 | F42: Average | G42: Std Dev | H42: Std Error | K42: Hours | L42: NF 1 | M42: NF 2 | N42: NF 3 | O42: NF 4 | P42: Average | Q42: Std Dev | R42: Std Error
A43: 20 | B43: =C3 -> 11.242 | C43: =C13 -> 9.544 | D43: =C23 -> 10.576 | E43: =C33 -> 7.596 | F43: =AVERAGE(B43:E43) -> 9.7395 | G43: =STDEV(B43:E43) -> 1.5906027 | H43: =G43/SQRT(4) -> 0.79530136 | K43: 20 | L43: =K3 -> 1.6605613 | M43: =K13 -> 8.7559633 | N43: =K23 -> 1.1001768 | O43: =K33 -> 1.1939642 | P43: =AVERAGE(L43:O43) -> 3.1776664 | Q43: =STDEV(L43:O43) -> 3.7269309 | R43: =Q43/SQRT(4) -> 1.8634654
A44: =A43+4 -> 24 | B44: =C4 -> 5.844 | C44: =C14 -> 3.415 | D44: =C24 -> 10.006 | E44: =C34 -> 7.54 | F44: =AVERAGE(B44,D44:E44) -> 7.7966667 | G44: =STDEV(B44,D44:E44) -> 2.0928376 | H44: =G44/SQRT(3) -> 1.2083004 | K44: =K43+4 -> 24 | L44: =K4 -> 0.60428084 | M44: =K14 -> 0.6016561 | N44: =K24 -> 1.4803965 | O44: =K34 -> 1.6662983 | P44: =AVERAGE(L44:O44) -> 1.0881579 | Q44: =STDEV(L44:O44) -> 0.5653667 | R44: =Q44/SQRT(4) -> 0.28268335
...

Sheet PM IV
A1: NF 1 PM IV | F1: NF 1 BiP | J1: NF 1 PM IV vs BiP
A2: Hours | B2: Area | C2: Percent | D2: Rel density | F2: Area | G2: Percent | H2: Rel density | J2: A PM I/ A BiP | K2: Percent/percent | L2: Rel Dens/Rel Dens
A3: 20 | B3: 4808.28 | C3: 6.32 | D3: =C3/$C$3 -> 1 | F3: 2125.72 | G3: 3.11 | H3: =G3/$G$3 -> 1 | J3: =B3/F3 -> 2.2619536 | K3: =C3/G3 -> 2.0321543 | L3: =K3/$K$9 -> 1.6470146
A4: =A3+4 -> 24 | B4: 172.36 | C4: 0.23 | D4: =C4/$C$3 -> 0.036392405 | F4: 4175.5 | G4: 6.1 | H4: =G4/$G$3 -> 1.9614148 | J4: =B4/F4 -> 0.041278889 | K4: =C4/G4 -> 0.037704918 | L4: =K4/$K$9 -> 0.030558974
A5: =A4+4 -> 28 | B5: 5307.1 | C5: 6.98 | D5: =C5/$C$3 -> 1.1044304 | F5: 5828.57 | G5: 8.52 | H5: =G5/$G$3 -> 2.7395498 | J5: =B5/F5 -> 0.91053209 | K5: =C5/G5 -> 0.81924883 | L5: =K5/$K$9 -> 0.66398245
A6: =A5+4 -> 32 | B6: 11831.78 | C6: 15.55 | D6: =C6/$C$3 -> 2.460443 | F6: 11269.54 | G6: 16.47 | H6: =G6/$G$3 -> 5.2958199 | J6: =B6/F6 -> 1.0498902 | K6: =C6/G6 -> 0.94414086 | L6: =K6/$K$9 -> 0.76520459
A7: =A6+4 -> 36 | B7: 13053.68 | C7: 17.16 | D7: =C7/$C$3 -> 2.7151899 | F7: 14168.2 | G7: 20.7 | H7: =G7/$G$3 -> 6.6559486 | J7: =B7/F7 -> 0.92133651 | K7: =C7/G7 -> 0.82898551 | L7: =K7/$K$9 -> 0.67187381
A8: =A7+4 -> 40 | B8: 18103.99 | C8: 23.8 | D8: =C8/$C$3 -> 3.7658228 | F8: 14243.32 | G8: 20.81 | H8: =G8/$G$3 -> 6.6913183 | J8: =B8/F8 -> 1.2710513 | K8: =C8/G8 -> 1.1436809 | L8: =K8/$K$9 -> 0.92692725
A9: =A8+4 -> 44 | B9: 22802.36 | C9: 29.97 | D9: =C9/$C$3 -> 4.7420886 | F9: 16619.85 | G9: 24.29 | H9: =G9/$G$3 -> 7.8102894 | J9: =B9/F9 -> 1.3719955 | K9: =C9/G9 -> 1.2338411 | L9: =K9/$K$9 -> 1
A11: NF 2 PM IV | F11: NF 2 BiP | J11: NF 2 PM IV vs BiP
A12: Hours | B12: Area | C12: Percent | D12: Rel Density | F12: Area | G12: Percent | H12: Rel Density | J12: A/A | K12: P/P | L12: Rel dens / Rel dens
A13: 20 | B13: 3159.2 | C13: 4.36 | D13: =C13/$C$13 -> 1 | F13: 662.87 | G13: 1.17 | H13: =G13/$G$13 -> 1 | J13: =B13/F13 -> 4.765942 | K13: =C13/G13 -> 3.7264957 | L13: =K13/$K$19 -> 4.0321968
A14: =A13+4 -> 24 | B14: 593.58 | C14: 0.82 | D14: =C14/$C$13 -> 0.18807339 | F14: 4146.2 | G14: 7.29 | H14: =G14/$G$13 -> 6.2307692 | J14: =B14/F14 -> 0.14316241 | K14: =C14/G14 -> 0.11248285 | L14: =K14/$K$19 -> 0.12171032
A15: =A14+4 -> 28 | B15: 5725.81 | C15: 7.9 | D15: =C15/$C$13 -> 1.8119266 | F15: 1106.53 | G15: 1.95 | H15: =G15/$G$13 -> 1.6666667 | J15: =B15/F15 -> 5.1745637 | K15: =C15/G15 -> 4.0512821 | L15: =K15/$K$19 -> 4.3836268
A16: =A15+4 -> 32 | B16: 12843.85 | C16: 17.72 | D16: =C16/$C$13 -> 4.0642202 | F16: 8303.18 | G16: 14.61 | H16: =G16/$G$13 -> 12.487179 | J16: =B16/F16 -> 1.5468592 | K16: =C16/G16 -> 1.2128679 | L16: =K16/$K$19 -> 1.3123649
A17: =A16+4 -> 36 | B17: 14214.39 | C17: 19.61 | D17: =C17/$C$13 -> 4.4977064 | F17: 12902.32 | G17: 22.7 | H17: =G17/$G$13 -> 19.401709 | J17: =B17/F17 -> 1.1016926 | K17: =C17/G17 -> 0.86387665 | L17: =K17/$K$19 -> 0.9347443
A18: =A17+4 -> 40 | B18: 18271.75 | C18: 25.21 | D18: =C18/$C$13 -> 5.7821101 | F18: 14721.15 | G18: 25.9 | H18: =G18/$G$13 -> 22.136752 | J18: =B18/F18 -> 1.2411904 | K18: =C18/G18 -> 0.97335907 | L18: =K18/$K$19 -> 1.0532081
A19: =A18+4 -> 44 | B19: 17668.22 | C19: 24.38 | D19: =C19/$C$13 -> 5.5917431 | F19: 14994.68 | G19: 26.38 | H19: =G19/$G$13 -> 22.547009 | J19: =B19/F19 -> 1.1782992 | K19: =C19/G19 -> 0.92418499 | L19: =K19/$K$19 -> 1
A21: NF 3 PM IV | F21: NF 3 BiP | J21: NF 3 PM IV vs BiP
A22: Hours | B22: Area | C22: Percent | D22: Rel Density | F22: Area | G22: Percent | H22: Rel Density | J22: A/A | K22: P/P | L22: Rel dens / Rel dens
A23: 20 | B23: 4065.569 | C23: 7.185 | D23: =C23/$C$13 -> 1.6479358 | F23: 6081.518 | G23: 8.761 | H23: =G23/$G$13 -> 7.4880342 | J23: =B23/F23 -> 0.6685122 | K23: =C23/G23 -> 0.82011186 | L23: =K23/$K$19 -> 0.88738929
A24: =A23+4 -> 24 | B24: 2819.154 | C24: 4.982 | D24: =C24/$C$13 -> 1.1426606 | F24: 3958.861 | G24: 5.703 | H24: =G24/$G$13 -> 4.874359 | J24: =B24/F24 -> 0.7121124 | K24: =C24/G24 -> 0.87357531 | L24: =K24/$K$19 -> 0.94523859
A25: =A24+4 -> 28 | B25: 6441.225 | C25: 11.383 | D25: =C25/$C$13 -> 2.6107798 | F25: 6647.64 | G25: 9.577 | H25: =G25/$G$13 -> 8.1854701 | J25: =B25/F25 -> 0.96894913 | K25: =C25/G25 -> 1.1885768 | L25: =K25/$K$19 -> 1.286081
A26: =A25+4 -> 32 | B26: 7573.468 | C26: 13.384 | D26: =C26/$C$13 -> 3.0697248 | F26: 9410.711 | G26: 13.557 | H26: =G26/$G$13 -> 11.587179 | J26: =B26/F26 -> 0.80477107 | K26: =C26/G26 -> 0.98723906 | L26: =K26/$K$19 -> 1.0682267
A27: =A26+4 -> 36 | B27: 13564.368 | C27: 23.971 | D27: =C27/$C$13 -> 5.4979358 | F27: 13505.338 | G27: 19.456 | H27: =G27/$G$13 -> 16.62906 | J27: =B27/F27 -> 1.0043709 | K27: =C27/G27 -> 1.2320621 | L27: =K27/$K$19 -> 1.3331336
A28: =A27+4 -> 40 | B28: 12131.075 | C28: 21.438 | D28: =C28/$C$13 -> 4.9169725 | F28: 13467.681 | G28: 19.402 | H28: =G28/$G$13 -> 16.582906 | J28: =B28/F28 -> 0.90075455 | K28: =C28/G28 -> 1.1049376 | L28: =K28/$K$19 -> 1.1955806
A29: =A28+4 -> 44 | B29: 9991.125 | C29: 17.657 | D29: =C29/$C$13 -> 4.0497706 | F29: 16341.631 | G29: 23.542 | H29: =G29/$G$13 -> 20.121368 | J29: =B29/F29 -> 0.61139093 | K29: =C29/G29 -> 0.75002124 | L29: =K29/$K$19 -> 0.81154882
A31: NF 4 PM IV | F31: NF 4 BiP | J31: NF 4 PM IV vs BiP
A32: Hours | B32: Area | C32: Percent | D32: Rel Density | F32: Area | G32: Percent | H32: Rel Density | J32: A/A | K32: P/P | L32: Rel dens / Rel dens
A33: 20 | B33: 8429.61 | C33: 11.242 | D33: =C33/$C$13 -> 2.5784404 | F33: 6501.347 | G33: 8.667 | H33: =G33/$G$13 -> 7.4076923 | J33: =B33/F33 -> 1.2965944 | K33: =C33/G33 -> 1.297104 | L33: =K33/$K$19 -> 1.4035112
A34: =A33+4 -> 24 | B34: 7541.61 | C34: 10.058 | D34: =C34/$C$13 -> 2.3068807 | F34: 4830.69 | G34: 6.44 | H34: =G34/$G$13 -> 5.5042735 | J34: =B34/F34 -> 1.5611869 | K34: =C34/G34 -> 1.5618012 | L34: =K34/$K$19 -> 1.6899228
A35: =A34+4 -> 28 | B35: 8149.56 | C35: 10.868 | D35: =C35/$C$13 -> 2.4926606 | F35: 3475.033 | G35: 4.633 | H35: =G35/$G$13 -> 3.9598291 | J35: =B35/F35 -> 2.3451749 | K35: =C35/G35 -> 2.3457803 | L35: =K35/$K$19 -> 2.5382151
A36: =A35+4 -> 32 | B36: 9924.095 | C36: 13.235 | D36: =C36/$C$13 -> 3.0355505 | F36: 7823.832 | G36: 10.43 | H36: =G36/$G$13 -> 8.9145299 | J36: =B36/F36 -> 1.2684443 | K36: =C36/G36 -> 1.2689358 | L36: =K36/$K$19 -> 1.3730322
A37: =A36+4 -> 36 | B37: 12881.167 | C37: 17.179 | D37: =C37/$C$13 -> 3.9401376 | F37: 12642.146 | G37: 16.854 | H37: =G37/$G$13 -> 14.405128 | J37: =B37/F37 -> 1.0189067 | K37: =C37/G37 -> 1.0192833 | L37: =K37/$K$19 -> 1.1028996
A38: =A37+4 -> 40 | B38: 13747.924 | C38: 18.334 | D38: =C38/$C$13 -> 4.2050459 | F38: 17815.359 | G38: 23.75 | H38: =G38/$G$13 -> 20.299145 | J38: =B38/F38 -> 0.77168942 | K38: =C38/G38 -> 0.77195789 | L38: =K38/$K$19 -> 0.83528504
A39: =A38+4 -> 44 | B39: 14310.045 | C39: 19.084 | D39: =C39/$C$13 -> 4.3770642 | F39: 21923.501 | G39: 29.227 | H39: =G39/$G$13 -> 24.980342 | J39: =B39/F39 -> 0.65272627 | K39: =C39/G39 -> 0.65295788 | L39: =K39/$K$19 -> 0.70652293
A41: Average of Percent values | J41: P/P Average
A42: Hours | B42: NF 1 | C42: NF 2 | D42: NF 3 | E42: NF 4 | F42: Average | G42: Std Dev | H42: Std Error | K42: Hours | L42: NF 1 | M42: NF 2 | N42: NF 3 | O42: NF 4 | P42: Average | Q42: Std Dev | R42: Std Error
A43: 20 | B43: =C3 -> 6.32 | C43: =C13 -> 4.36 | D43: =C23 -> 7.185 | E43: =C33 -> 11.242 | F43: =AVERAGE(B43:E43) -> 7.27675 | G43: =STDEV(B43:E43) -> 2.8956535 | H43: =G43/SQRT(4) -> 1.4478267 | K43: 20 | L43: =K3 -> 2.0321543 | M43: =K13 -> 3.7264957 | N43: =K23 -> 0.82011186 | O43: =K33 -> 1.297104 | P43: =AVERAGE(L43,N43:O43) -> 1.3831234 | Q43: =STDEV(L43,N43:O43) -> 0.61058271 | R43: =Q43/SQRT(3) -> 0.35252009
A44: =A43+4 -> 24 | B44: =C4 -> 0.23 | C44: =C14 -> 0.82 | D44: =C24 -> 4.982 | E44: =C34 -> 10.058 | F44: =AVERAGE(C44:E44) -> 5.2866667 | G44: =STDEV(C44:E44) -> 4.6265297 | H44: =G44/SQRT(3) -> 2.6711282 | K44: =K43+4 -> 24 | L44: =K4 -> 0.037704918 | M44: =K14 -> 0.11248285 | N44: =K24 -> 0.87357531 | O44: =K34 -> 1.5618012 | P44: =AVERAGE(M44:O44) -> 0.84928647 | Q44: =STDEV(M44:O44) -> 0.72496442 | R44: =Q44/SQRT(3) -> 0.4185584
...

Sheet Volume
A1: Time | B1: Volume | C1: PMI (1) | D1: Enzyme/Volume | G1: Time | H1: Volume | I1: PMI (2) | J1: Enzyme/Volume | L1: Time | M1: Volume | N1: PMI (3) | O1: Enzyme/Volume | Q1: Time | R1: Volume | S1: PMI (4) | T1: Enzyme/Volume
A2: 20 | B2: 0.32 | C2: ='PM I'!C3 -> 11.242 | D2: =C2/B2 -> 35.13125 | G2: 20 | H2: 0.32 | I2: ='PM I'!C13 -> 9.544 | J2: =I2/H2 -> 29.825 | L2: 20 | M2: 0.32 | N2: ='PM I'!C23 -> 10.576 | O2: =N2/M2 -> 33.05 | Q2: 20 | R2: 0.32 | S2: ='PM I'!C33 -> 7.596 | T2: =S2/R2 -> 23.7375
A3: =A2+4 -> 24 | B3: 0.374 | C3: ='PM I'!C4 -> 5.844 | D3: =C3/B3 -> 15.625668 | G3: =G2+4 -> 24 | H3: 0.374 | I3: ='PM I'!C14 -> 3.415 | J3: =I3/H3 -> 9.131016 | L3: =L2+4 -> 24 | M3: 0.374 | N3: ='PM I'!C24 -> 10.006 | O3: =N3/M3 -> 26.754011 | Q3: =Q2+4 -> 24 | R3: 0.374 | S3: ='PM I'!C34 -> 7.54 | T3: =S3/R3 -> 20.160428
A4: =A3+4 -> 28 | B4: 0.9386 | C4: ='PM I'!C5 -> 12.439 | D4: =C4/B4 -> 13.252717 | G4: =G3+4 -> 28 | H4: 0.9386 | I4: ='PM I'!C15 -> 8.943 | J4: =I4/H4 -> 9.5280205 | L4: =L3+4 -> 28 | M4: 0.9386 | N4: ='PM I'!C25 -> 11.772 | O4: =N4/M4 -> 12.542084 | Q4: =Q3+4 -> 28 | R4: 0.9386 | S4: ='PM I'!C35 -> 11.471 | T4: =S4/R4 -> 12.221394
A5: =A4+4 -> 32 | B5: 1.678 | C5: ='PM I'!C6 -> 15.033 | D5: =C5/B5 -> 8.9588796 | G5: =G4+4 -> 32 | H5: 1.678 | I5: ='PM I'!C16 -> 18.227 | J5: =I5/H5 -> 10.862336 | L5: =L4+4 -> 32 | M5: 1.678 | N5: ='PM I'!C26 -> 16.345 | O5: =N5/M5 -> 9.7407628 | Q5: =Q4+4 -> 32 | R5: 1.678 | S5: ='PM I'!C36 -> 15.219 | T5: =S5/R5 -> 9.0697259
A6: =A5+4 -> 36 | B6: 2.75 | C6: ='PM I'!C7 -> 16.113 | D6: =C6/B6 -> 5.8592727 | G6: =G5+4 -> 36 | H6: 2.75 | I6: ='PM I'!C17 -> 18.288 | J6: =I6/H6 -> 6.6501818 | L6: =L5+4 -> 36 | M6: 2.75 | N6: ='PM I'!C27 -> 19.439 | O6: =N6/M6 -> 7.0687273 | Q6: =Q5+4 -> 36 | R6: 2.75 | S6: ='PM I'!C37 -> 15.051 | T6: =S6/R6 -> 5.4730909
A7: =A6+4 -> 40 | B7: 2.812 | C7: ='PM I'!C8 -> 19.209 | D7: =C7/B7 -> 6.8310811 | G7: =G6+4 -> 40 | H7: 2.812 | I7: ='PM I'!C18 -> 19.537 | J7: =I7/H7 -> 6.947724 | L7: =L6+4 -> 40 | M7: 2.812 | N7: ='PM I'!C28 -> 17.581 | O7: =N7/M7 -> 6.2521337 | Q7: =Q6+4 -> 40 | R7: 2.812 | S7: ='PM I'!C38 -> 22.18 | T7: =S7/R7 -> 7.8876245
A8: =A7+4 -> 44 | B8: 1.197 | C8: ='PM I'!C9 -> 20.12 | D8: =C8/B8 -> 16.808688 | G8: =G7+4 -> 44 | H8: 1.197 | I8: ='PM I'!C19 -> 22.046 | J8: =I8/H8 -> 18.417711 | L8: =L7+4 -> 44 | M8: 1.197 | N8: ='PM I'!C29 -> 14.281 | O8: =N8/M8 -> 11.93066 | Q8: =Q7+4 -> 44 | R8: 1.197 | S8: ='PM I'!C39 -> 20.945 | T8: =S8/R8 -> 17.497911
A11: Time | B11: Volume | C11: PMIV (1) | D11: Enzyme/Volume | G11: Time | H11: Volume | I11: PMIV (2) | J11: Enzyme/Volume | L11: Time | M11: Volume | N11: PMIV (3) | O11: Enzyme/Volume | Q11: Time | R11: Volume | S11: PMIV (4) | T11: Enzyme/Volume
A12: 20 | B12: 0.32 | C12: ='PM IV'!C3 -> 6.32 | D12: =C12/B12 -> 19.75 | G12: 20 | H12: 0.32 | I12: ='PM IV'!C13 -> 4.36 | J12: =I12/H12 -> 13.625 | L12: 20 | M12: 0.32 | N12: ='PM IV'!C23 -> 7.185 | O12: =N12/M12 -> 22.453125 | Q12: 20 | R12: 0.32 | S12: ='PM IV'!C33 -> 11.242 | T12: =S12/R12 -> 35.13125
A13: =A12+4 -> 24 | B13: 0.374 | C13: ='PM IV'!C4 -> 0.23 | D13: =C13/B13 -> 0.61497326 | G13: =G12+4 -> 24 | H13: 0.374 | I13: ='PM IV'!C14 -> 0.82 | J13: =I13/H13 -> 2.1925134 | L13: =L12+4 -> 24 | M13: 0.374 | N13: ='PM IV'!C24 -> 4.982 | O13: =N13/M13 -> 13.320856 | Q13: =Q12+4 -> 24 | R13: 0.374 | S13: ='PM IV'!C34 -> 10.058 | T13: =S13/R13 -> 26.893048
A14: =A13+4 -> 28 | B14: 0.9386 | C14: ='PM IV'!C5 -> 6.98 | D14: =C14/B14 -> 7.4366077 | G14: =G13+4 -> 28 | H14: 0.9386 | I14: ='PM IV'!C15 -> 7.9 | J14: =I14/H14 -> 8.416791 | L14: =L13+4 -> 28 | M14: 0.9386 | N14: ='PM IV'!C25 -> 11.383 | O14: =N14/M14 -> 12.127637 | Q14: =Q13+4 -> 28 | R14: 0.9386 | S14: ='PM IV'!C35 -> 10.868 | T14: =S14/R14 -> 11.578947
A15: =A14+4 -> 32 | B15: 1.678 | C15: ='PM IV'!C6 -> 15.55 | D15: =C15/B15 -> 9.2669845 | G15: =G14+4 -> 32 | H15: 1.678 | I15: ='PM IV'!C16 -> 17.72 | J15: =I15/H15 -> 10.560191 | L15: =L14+4 -> 32 | M15: 1.678 | N15: ='PM IV'!C26 -> 13.384 | O15: =N15/M15 -> 7.9761621 | Q15: =Q14+4 -> 32 | R15: 1.678 | S15: ='PM IV'!C36 -> 13.235 | T15: =S15/R15 -> 7.8873659
A16: =A15+4 -> 36 | B16: 2.75 | C16: ='PM IV'!C7 -> 17.16 | D16: =C16/B16 -> 6.24 | G16: =G15+4 -> 36 | H16: 2.75 | I16: ='PM IV'!C17 -> 19.61 | J16: =I16/H16 -> 7.1309091 | L16: =L15+4 -> 36 | M16: 2.75 | N16: ='PM IV'!C27 -> 23.971 | O16: =N16/M16 -> 8.7167273 | Q16: =Q15+4 -> 36 | R16: 2.75 | S16: ='PM IV'!C37 -> 17.179 | T16: =S16/R16 -> 6.2469091
A17: =A16+4 -> 40 | B17: 2.812 | C17: ='PM IV'!C8 -> 23.8 | D17: =C17/B17 -> 8.4637269 | G17: =G16+4 -> 40 | H17: 2.812 | I17: ='PM IV'!C18 -> 25.21 | J17: =I17/H17 -> 8.9651494 | L17: =L16+4 -> 40 | M17: 2.812 | N17: ='PM IV'!C28 -> 21.438 | O17: =N17/M17 -> 7.6237553 | Q17: =Q16+4 -> 40 | R17: 2.812 | S17: ='PM IV'!C38 -> 18.334 | T17: =S17/R17 -> 6.5199147
A18: =A17+4 -> 44 | B18: 1.197 | C18: ='PM IV'!C9 -> 29.97 | D18: =C18/B18 -> 25.037594 | G18: =G17+4 -> 44 | H18: 1.197 | I18: ='PM IV'!C19 -> 24.38 | J18: =I18/H18 -> 20.367586 | L18: =L17+4 -> 44 | M18: 1.197 | N18: ='PM IV'!C29 -> 17.657 | O18: =N18/M18 -> 14.751044 | Q18: =Q17+4 -> 44 | R18: 1.197 | S18: ='PM IV'!C39 -> 19.084 | T18: =S18/R18 -> 15.943191
